Workbook

Sheet Meals_Weekly_Pattern
A1: Weekly Meals Planner (auto-fills from Meal_Library)
A2: Change Day Type via dropdown to auto-fill meals. Default pattern matches your Mon–Sun training week.
A3: Day | B3: Day Type | C3: Portion | D3: Breakfast | E3: Snack | F3: Lunch / Pre | G3: Post | H3: Dinner
A4: Monday | B4: Ruck | C4: Standard | D4: =IFERROR(VLOOKUP($B4,Meal_Library!$A$3:$G$7,2,FALSE),"") -> Overnight oats (Long‑day): ¾c oats + milk + yogurt + berries/banana + chia OR flax + cinnamon (optional whey) | E4: =IFERROR(VLOOKUP($B4,Meal_Library!$A$3:$G$7,3,FALSE),"") -> 10am top‑off: 2 energy balls OR banana OR Greek yogurt + berries | F4: =IFERROR(VLOOKUP($B4,Meal_Library!$A$3:$G$7,4,FALSE),"") -> 12pm fuel: Chicken + rice + veggies bowl (light salt; vinegar/lime) | G4: =IFERROR(VLOOKUP($B4,Meal_Library!$A$3:$G$7,5,FALSE),"") -> 3–4pm recovery: Tuna + Greek‑yogurt bowl (or chicken+rice/beans if very depleted) | H4: =IFERROR(VLOOKUP($B4,Meal_Library!$A$3:$G$7,6,FALSE),"") -> 6pm dinner: Bean/lentil chili + big salad (finish by ~7pm)
A5: Tuesday | B5: Strength | C5: Standard | D5: =IFERROR(VLOOKUP($B5,Meal_Library!$A$3:$G$7,2,FALSE),"") -> Egg scramble + spinach/onion/peppers + mini oats (½c) OR toast | E5: =IFERROR(VLOOKUP($B5,Meal_Library!$A$3:$G$7,3,FALSE),"") -> Greek yogurt + berries + cinnamon | F5: =IFERROR(VLOOKUP($B5,Meal_Library!$A$3:$G$7,4,FALSE),"") -> Power bowl: Beans + rice + chicken + homemade salsa | G5: =IFERROR(VLOOKUP($B5,Meal_Library!$A$3:$G$7,5,FALSE),"") -> Whey shake: 1 scoop + milk/soy + berries (add ¼c oats if hungry) | H5: =IFERROR(VLOOKUP($B5,Meal_Library!$A$3:$G$7,6,FALSE),"") -> Chicken thighs + roasted veggies (+ small carb if depleted)
A6: Wednesday | B6: Swim | C6: Standard | D6: =IFERROR(VLOOKUP($B6,Meal_Library!$A$3:$G$7,2,FALSE),"") -> Overnight oats (Light): ½c oats + milk + yogurt + berries + chia OR flax | E6: =IFERROR(VLOOKUP($B6,Meal_Library!$A$3:$G$7,3,FALSE),"") -> Optional pre‑swim: banana (optional 1 tbsp PB) | F6: =IFERROR(VLOOKUP($B6,Meal_Library!$A$3:$G$7,4,FALSE),"") -> Lentil salad bowl (+ tuna/chicken if desired) | G6: =IFERROR(VLOOKUP($B6,Meal_Library!$A$3:$G$7,5,FALSE),"") -> Energy balls if hungry | H6: =IFERROR(VLOOKUP($B6,Meal_Library!$A$3:$G$7,6,FALSE),"") -> Tuna Mediterranean plate + big salad (small carb if needed)
A7: Thursday | B7: Strength | C7: Standard | D7: =IFERROR(VLOOKUP($B7,Meal_Library!$A$3:$G$7,2,FALSE),"") -> Egg scramble + spinach/onion/peppers + mini oats (½c) OR toast | E7: =IFERROR(VLOOKUP($B7,Meal_Library!$A$3:$G$7,3,FALSE),"") -> Greek yogurt + berries + cinnamon | F7: =IFERROR(VLOOKUP($B7,Meal_Library!$A$3:$G$7,4,FALSE),"") -> Power bowl: Beans + rice + chicken + homemade salsa | G7: =IFERROR(VLOOKUP($B7,Meal_Library!$A$3:$G$7,5,FALSE),"") -> Whey shake: 1 scoop + milk/soy + berries (add ¼c oats if hungry) | H7: =IFERROR(VLOOKUP($B7,Meal_Library!$A$3:$G$7,6,FALSE),"") -> Chicken thighs + roasted veggies (+ small carb if depleted)
A8: Friday | B8: Ruck | C8: Standard | D8: =IFERROR(VLOOKUP($B8,Meal_Library!$A$3:$G$7,2,FALSE),"") -> Overnight oats (Long‑day): ¾c oats + milk + yogurt + berries/banana + chia OR flax + cinnamon (optional whey) | E8: =IFERROR(VLOOKUP($B8,Meal_Library!$A$3:$G$7,3,FALSE),"") -> 10am top‑off: 2 energy balls OR banana OR Greek yogurt + berries | F8: =IFERROR(VLOOKUP($B8,Meal_Library!$A$3:$G$7,4,FALSE),"") -> 12pm fuel: Chicken + rice + veggies bowl (light salt; vinegar/lime) | G8: =IFERROR(VLOOKUP($B8,Meal_Library!$A$3:$G$7,5,FALSE),"") -> 3–4pm recovery: Tuna + Greek‑yogurt bowl (or chicken+rice/beans if very depleted) | H8: =IFERROR(VLOOKUP($B8,Meal_Library!$A$3:$G$7,6,FALSE),"") -> 6pm dinner: Bean/lentil chili + big salad (finish by ~7pm)
A9: Saturday | B9: Rest/Recovery | C9: Standard | D9: =IFERROR(VLOOKUP($B9,Meal_Library!$A$3:$G$7,2,FALSE),"") -> Overnight oats (Light) OR eggs + veg | E9: =IFERROR(VLOOKUP($B9,Meal_Library!$A$3:$G$7,3,FALSE),"") -> Fruit + Greek yogurt (or skip if not hungry) | F9: =IFERROR(VLOOKUP($B9,Meal_Library!$A$3:$G$7,4,FALSE),"") -> Big salad + beans/lentils + tuna/chicken | G9: =IFERROR(VLOOKUP($B9,Meal_Library!$A$3:$G$7,5,FALSE),"") -> Optional: whey only if protein is low | H9: =IFERROR(VLOOKUP($B9,Meal_Library!$A$3:$G$7,6,FALSE),"") -> Protein + veggies; carbs lower/moderate
A10: Sunday | B10: Cycle | C10: Standard | D10: =IFERROR(VLOOKUP($B10,Meal_Library!$A$3:$G$7,2,FALSE),"") -> Overnight oats (Long‑day) OR eggs + toast + fruit (savory option) | E10: =IFERROR(VLOOKUP($B10,Meal_Library!$A$3:$G$7,3,FALSE),"") -> 10am top‑off: 2 energy balls OR banana | F10: =IFERROR(VLOOKUP($B10,Meal_Library!$A$3:$G$7,4,FALSE),"") -> Pre: Rice + chicken bowl (or beans+rice if tolerated) | G10: =IFERROR(VLOOKUP($B10,Meal_Library!$A$3:$G$7,5,FALSE),"") -> Post: Whey shake + berries | H10: =IFERROR(VLOOKUP($B10,Meal_Library!$A$3:$G$7,6,FALSE),"") -> Dinner: Protein + veggies + carb as needed
A12: Portion guidance
A13: Small = lighter day / lower hunger • Standard = default steady cut • Big = long/hard day (increase carbs at breakfast + recovery meal)

Sheet Meal_Library
A1: Meal Library (edit text here to update the weekly planner)
A2: Day Type | B2: Breakfast | C2: Snack | D2: Lunch / Pre | E2: Post | F2: Dinner | G2: Notes
A3: Ruck | B3: Overnight oats (Long‑day): ¾c oats + milk + yogurt + berries/banana + chia OR flax + cinnamon (optional whey) | C3: 10am top‑off: 2 energy balls OR banana OR Greek yogurt + berries | D3: 12pm fuel: Chicken + rice + veggies bowl (light salt; vinegar/lime) | E3: 3–4pm recovery: Tuna + Greek‑yogurt bowl (or chicken+rice/beans if very depleted) | F3: 6pm dinner: Bean/lentil chili + big salad (finish by ~7pm) | G3: Start fueling 30–45 min in; sweet snacks OK; keep sodium lower at dinner if you used salty intra fuel.
A4: Strength | B4: Egg scramble + spinach/onion/peppers + mini oats (½c) OR toast | C4: Greek yogurt + berries + cinnamon | D4: Power bowl: Beans + rice + chicken + homemade salsa | E4: Whey shake: 1 scoop + milk/soy + berries (add ¼c oats if hungry) | F4: Chicken thighs + roasted veggies (+ small carb if depleted) | G4: Focus protein; avoid heavy/fried fats pre‑lift.
A5: Swim | B5: Overnight oats (Light): ½c oats + milk + yogurt + berries + chia OR flax | C5: Optional pre‑swim: banana (optional 1 tbsp PB) | D5: Lentil salad bowl (+ tuna/chicken if desired) | E5: Energy balls if hungry | F5: Tuna Mediterranean plate + big salad (small carb if needed) | G5: Keep it light before swim; refuel after.
A6: Cycle | B6: Overnight oats (Long‑day) OR eggs + toast + fruit (savory option) | C6: 10am top‑off: 2 energy balls OR banana | D6: Pre: Rice + chicken bowl (or beans+rice if tolerated) | E6: Post: Whey shake + berries | F6: Dinner: Protein + veggies + carb as needed | G6: For 5–6h rides: steady sipping + snacks every 20–30 min.
A7: Rest/Recovery | B7: Overnight oats (Light) OR eggs + veg | C7: Fruit + Greek yogurt (or skip if not hungry) | D7: Big salad + beans/lentils + tuna/chicken | E7: Optional: whey only if protein is low | F7: Protein + veggies; carbs lower/moderate | G7: Lower sodium, higher veggies/fiber.

Sheet Meals_3Day_Plan
A1: 3‑Day Meal Plan (Steady Cut) — Meals & Recipes
A2: Scope | B2: Meals only: recipes, macros, groceries, restaurant ordering. Built for endurance + strength with 11am long-day starts and last calories by ~7pm.
A4: Daily Timing
A5: Time | B5: Action
A6: 6:00am | B6: Water (20 oz)
A7: 6:30–7:00am | B7: Breakfast (overnight oats)
A8: 10:00am | B8: Top‑off snack (2 energy balls OR banana OR Greek yogurt + berries)
A9: 11:00am | B9: Start long hike/cycle — sip drink mix early; start snacks 30–45 min in
A10: 2:00–3:00pm | B10: Finish — rehydrate; Recovery Meal
A11: 5:00pm | B11: Optional protein snack (whey shake or Greek yogurt)
A12: 6:00–6:30pm | B12: Dinner (finish by 6:45–7:00pm)
A13: Night | B13: Chamomile or lemon balm tea (no sweeteners)
A15: 3‑Day Plan
A16: Day | B16: Meals (summary)
A17: Day 1 (Mon) — Ruck day | B17: Breakfast: Overnight oats (Long‑day) Snack: 2 energy balls Lunch (pre‑ruck): Chicken + rice + veggies bowl Post: Tuna + Greek‑yogurt salad bowl Dinner: Instant Pot bean/lentil chili + salad
A18: Day 2 (Tue) — Strength day | B18: Breakfast: Eggs + spinach scramble + mini oats Snack: Greek yogurt + berries Lunch (pre‑lift): Beans + rice + chicken power bowl + homemade salsa Post‑lift: Whey shake + berries (add oats if hungry) Dinner: Air‑fryer/oven chicken thighs + roasted veggies (+ small carb if depleted)
A19: Day 3 (Wed) — Swim + walk day | B19: Breakfast: Overnight oats (Light) Pre‑swim snack: Banana (optional 1 tbsp PB) Lunch: Lentil salad bowl (add tuna/chicken if desired) Snack: Energy balls if hungry Dinner: Tuna Mediterranean plate + big salad (add small carb if needed)
A21: Fine‑tunes
A22: • Use thighs for meal prep (juicy, reheats well). • Make one blender salsa batch for the next 3 days. • Choose high‑protein milk (ultrafiltered dairy or unsweet soy). • Keep ACV mainly as a dressing ingredient. • Night tea: chamomile (or lemon balm).
A24: Recipes (details)
A25: Overnight Oats — Long‑day (more fuel)
A26: • ¾ cup rolled oats + 1 cup high‑protein milk (ultrafiltered dairy OR unsweet soy) • ½ cup plain/Greek yogurt + 1 cup berries (or 1 banana) • 1 tbsp chia OR flax + cinnamon • Optional: 1 scoop whey mixed in
A28: Overnight Oats — Light/rest version
A29: • ½ cup oats + ¾–1 cup milk + ½ cup yogurt • ½–1 cup berries + 1 tbsp chia OR flax + cinnamon • Optional: 1 tbsp peanut butter (measure it)
A31: Freezer Energy Balls (no‑bake, ~18 balls)
A32: • 2 cups oats; 1 cup natural peanut butter; ½ cup ground flax OR chia • ⅓ cup honey/maple; 1 tsp cinnamon; pinch salt • Optional: 1 scoop whey; optional mini dark choc chips or dried berries • Mix → roll balls → freeze 30–60 min → store freezer/fridge • Trail use: 1 ball every 20–30 min (or 2 balls every 40–60 min)
A34: Chicken — best cuts
A35: • Default: boneless skinless thighs (juicy; reheat well). • Leaner: breast (use thermometer + don’t overcook).
A37: Chicken — cooking methods (juicy, meal prep friendly)
... A59: • Chamomile tea (best default). • Lemon balm tea (deeper relaxation). • Ginger or peppermint tea (peppermint can worsen reflux for some). • No sweeteners; make it a consistent wind‑down ritual.

Sheet Templates
A1: Adrian — Master Training Templates (Whitney-focused)
A3: Warm-ups (copy/paste as needed)
A4: Ruck / Walk (8–10 min) | C4: • 3 min easy walk • 10 ankle circles each direction/side • 10 ankle rocks (knee over toes gently) • 10 slow calf raises • 8–10 glute bridges • 8–10 hip hinges • Pack fit check: hip belt first, load high/close
A5: Strength (6–8 min) | C5: • 3 min easy cardio (bike / incline walk) • 2 rounds: 8 bodyweight squats to a box (shallow), 10 band pull-aparts, 10 hip hinges • 1 warm-up set for first 2 lifts
A6: Swim (5–8 min) | C6: • 2–4 lengths very easy • 2 lengths backstroke (optional) • 2 x 20 sec relaxed exhale practice in shallow end
A7: Cycling (8–10 min) | C7: • 5 min easy spin • 3 x 30 sec faster cadence (easy effort) with 60 sec easy between • Start main ride only after breathing feels calm
A9: Cool-downs (copy/paste as needed)
A10: Ruck / Walk (8–12 min) | C10: • 8–10 min easy walk • Calf stretch (straight knee) 45 sec/side • Soleus stretch (bent knee) 45 sec/side • 3–5 slow breaths (exhale 4–6 sec)
A11: Strength (5–8 min) | C11: • 3–5 min easy walk • Upper back stretch 30–45 sec • Hip flexor stretch 30–45 sec/side
A12: Swim (5 min) | C12: • 2–4 easy lengths • Shoulder/chest opener 30–45 sec • Calf stretch 30–45 sec/side
A13: Cycling (6–10 min) | C13: • 5–8 min easy spin • Calf + hip flexor stretch 45 sec/side
A15: Massage & Recovery Tools (10–15 min typical)
A16: After ruck (best ROI): 1) Foot massager: 2–5 min/foot 2) Foam roller: calves 60–90s/side → quads 60s/side → glutes 60s/side → upper back 60s 3) Massage stick: calves/Achilles area 60s/side + shins 30–45s/side (gentle) Before workouts (optional): • 30–60 sec light rolling on calves/feet if stiff, then warm-up Recovery days (yes): • Keep it light (5–10 min). Goal = feel better, not bruised.
A21: Breathing (Whitney-style)
A22: • Zone 2 default: conversational pace (full sentences) • Pressure-breath on climbs: inhale 2–3 sec, exhale 4–6 sec • Cadence cue: small steps, tall chest, soft shoulders • If you feel panicky at altitude: slow down, lengthen exhale, keep moving steadily.
A26: HR Zones (fill after 1–2 HRM 200 sessions)
A27: Enter your zones here once you have data (we'll help you set these).
A28: Zone | B28: Description | C28: HR Range (bpm) | D28: Notes
A29: Z1 | B29: Recovery / very easy
A30: Z2 | B30: Base / conversational | D30: Most rucks/walks/rides here
A31: Z3 | B31: Steady / moderate
A32: Z4 | B32: Hard intervals
A33: Z5 | B33: Max / very hard

Sheet Week 1
A1: Week 1 — Whitney Prep (Training Log)
A2: Week start (Mon): | B2: 46089 | C2: Pack target (lb): | D2: 20 | E2: Sleep target: | F2: 8h (aim 10:00pm) | G2: Notes:
A4: Day | B4: Date | C4: Start | D4: Planned Session | E4: Location/Route | F4: Plan Duration | G4: Plan Dist | H4: Pack (lb) | I4: Intensity / Focus | J4: Warm-up | K4: Cool-down | L4: Actual Duration | M4: Actual Dist | N4: Avg HR | O4: Max HR | P4: RPE | Q4: Ailments/Notes
A5: Mon | B5: =IF($B$2="","",$B$2+0) -> 46089 | C5: 1:00 PM | D5: Ruck — Hill time (steady) | E5: Arroyo Verde (choose smooth climbs) | F5: 75–90 min | G5: N/A (time-based) | H5: 18–20 | I5: Conversational; slow on descents | J5: Templates: Ruck/Walk | K5: Templates: Ruck/Walk
A6: Tue | B6: =IF($B$2="","",$B$2+1) -> 46090 | C6: 5PM | D6: YMCA Strength — Upper + carries + core | E6: Ventura YMCA | F6: 60–75 min | I6: RIR 2 (leave 2 reps in reserve) | J6: Templates: Strength | K6: Templates: Strength | L6: 1 Hour 45 Minutes | Q6: 10 minutes of cardio for warm up, 1 hour and 20 minutes for workout, 15 minutes for cardio.
A7: Wed | B7: =IF($B$2="","",$B$2+2) -> 46091 | C7: 10:00 AM | D7: Swim (technique + easy aerobic) + PM brisk walk | E7: YMCA pool + flat route | F7: 60 min swim + 45–75 min walk (2pm) | I7: Easy aerobic + recovery walk | J7: Templates: Swim / Walk | K7: Templates: Swim / Walk
A8: Thu | B8: =IF($B$2="","",$B$2+3) -> 46092 | C8: 1PM | D8: Ruck — Base (flat/rolling) | E8: Harbor route (stable surfaces) | F8: 90–120 min | G8: (miles optional) | H8: 18–20 | I8: Easy; steady rhythm | J8: Templates: Ruck/Walk | K8: Templates: Ruck/Walk
A9: Fri | B9: =IF($B$2="","",$B$2+4) -> 46093 | C9: 0.625 | D9: YMCA Strength — Upper + carries + core | E9: Ventura YMCA | F9: 60–75 min | I9: RIR 2 (leave 2 reps in reserve) | J9: Templates: Strength | K9: Templates: Strength
A10: Sat | B10: =IF($B$2="","",$B$2+5) -> 46094 | C10: 0.5 | D10: Cycling (Zone 2 base) | E10: Home→Ojai or preferred route | F10: 60–180 min | G10: 30–45 mi | I10: Conversational effort | J10: Templates: Cycling | K10: Templates: Cycling
A11: Sun | B11: =IF($B$2="","",$B$2+6) -> 46095 | C11: (choose) | D11: Active recovery (easy swim / mobility / walk) | E11: YMCA or outdoors | F11: 30–60 min | I11: Very easy | J11: Templates | K11: Templates
A13: Strength Log — Tuesday (Upper + Carries + Core)
A14: Exercise | B14: Sets | C14: Reps/Length | D14: Plan Wt | E14: Actual Wt | F14: Notes
A15: Chest press (machine) | B15: 3 | C15: 12 | F15: Warm Up: 10Lbs per side, 2 Sets of 12 Reps. Workout: Set 1: 45LBS. Set 2: 45lbs. Set 3: 40lbs. 12 Reps per set
A16: Lat pulldown (machine) | B16: 3 | C16: 12 | F16: Warm Up Weight: 55lbs 2 Sets of 12 Reps. Workout: Set 1: 100lbs. Set 2: 100lbs. Set 3: 80. 12 Reps per set
A17: Seated row (machine) | B17: 3 | C17: 12 | F17: Warm Up: 55lbs 2 Sets of 12 Reps. Workout: Set 1: 120lbs Set 2: 120lbs Set 3: 100lbs. 12 Reps per set
A18: DB incline or flat press | B18: 3 | C18: 12 | F18: Warm Up: 15lbs 2 Sets of 12 Reps. Workout: Set 1 : 35lbs. Set 2: 35lbs. Set 3: 25lbs. 12 Reps per set
A19: Face pulls / rear delts | B19: 3 | C19: 12 | F19: Warm Up: 25lbs. 2 Set of 12 Reps. Workout: Set 1: 55lbs. Set 2: 55lbs. Set 3: 50lbs. 12 Reps per set
A20: Assited Pull-Ups | B20: 4 | C20: 12 | F20: Set Assited Weights to 175lbs for all 4 sets
A21: Assisted Dips | B21: 4 | C21: 12 | F21: Set Assited Weights to 175lbs for all 4 sets
A22: Farmer carry | B22: 3 | C22: 70–85 yd | F22: Warm Up: 15lbs Length Side. Workout: 50lbs Length Side. 40lbs Length Side. 30lbs Length Side. Perform farmers carry on artifical grass outdoor area.
A23: Dead bug | B23: 3 | C23: 12/side | D23: BW | F23: 2 sets of 12 reps per side
A24: Plank | B24: 3 | C24: 30s | D24: BW | F24: 3 sets of 30 seconds
A26: Strength Log — Friday (Upper + Carries + Core)
A27: Exercise | B27: Sets | C27: Reps | D27: Plan Wt | E27: Actual Wt | F27: Notes
A28: Chest press (machine) | B28: 3 | C28: 12 | F28: Warm Up: 10Lbs per side, 2 Sets of 12 Reps. Workout: Set 1: 45LBS. Set 2: 45lbs. Set 3: 40lbs. 12 Reps per set
A29: Lat pulldown (machine) | B29: 3 | C29: 12 | F29: Warm Up Weight: 55lbs 2 Sets of 12 Reps. Workout: Set 1: 100lbs. Set 2: 100lbs. Set 3: 80. 12 Reps per set
A30: Seated row (machine) | B30: 3 | C30: 12 | F30: Warm Up: 55lbs 2 Sets of 12 Reps. Workout: Set 1: 120lbs Set 2: 120lbs Set 3: 100lbs. 12 Reps per set
A31: DB incline or flat press | B31: 3 | C31: 12 | F31: Warm Up: 15lbs 2 Sets of 12 Reps. Workout: Set 1 : 35lbs. Set 2: 35lbs. Set 3: 25lbs. 12 Reps per set
A32: Face pulls / rear delts | B32: 3 | C32: 12 | F32: Warm Up: 25lbs. 2 Set of 12 Reps. Workout: Set 1: 55lbs. Set 2: 55lbs. Set 3: 50lbs. 12 Reps per set
A33: Assited Pull-Ups | B33: 4 | C33: 12 | F33: Set Assited Weights to 175lbs for all 4 sets
A34: Assisted Dips | B34: 4 | C34: 12 | F34: Set Assited Weights to 175lbs for all 4 sets
A35: Farmer carry | B35: 3 | C35: 70–85 yd | F35: Warm Up: 15lbs Length Side. Workout: 50lbs Length Side. 40lbs Length Side. 30lbs Length Side. Perform farmers carry on artifical grass outdoor area.
A36: Dead bug | B36: 3 | C36: 12/side | D36: BW | F36: 2 sets of 12 reps per side
A37: Plank | B37: 3 | C37: 30s | D37: BW | F37: 3 sets of 30 seconds
A39: Swim Log (Wed 10–11am or Sat Recovery Swim)
A40: Session | B40: Total yards | C40: Main set | D40: Rest | E40: Avg HR | F40: Notes
A41: Planned | B41: 350 yd | C41: 6×25 easy + 4×25 steady + 4×25 easy | D41: 30–45s between lengths
A43: Weekly Summary (auto where possible)
A44: Total ruck miles
A45: Total walk miles
...

Sheet Week 2
A1: Week 2 — Whitney Prep (Training Log)
A2: Week start (Mon): | B2: 46069 | C2: Pack target (lb): | D2: 18–20 | E2: Sleep target: | F2: 8h (aim 10:00pm) | G2: Notes:
A4: Day | B4: Date | C4: Start | D4: Planned Session | E4: Location/Route | F4: Plan Duration | G4: Plan Dist | H4: Pack (lb) | I4: Intensity / Focus | J4: Warm-up | K4: Cool-down | L4: Actual Duration | M4: Actual Dist | N4: Avg HR | O4: Max HR | P4: RPE | Q4: Ailments/Notes
A5: Mon | B5: =IF($B$2="","",$B$2+0) -> 46069 | C5: 1:00 PM | D5: Ruck — Hill time (steady) | E5: Arroyo Verde (choose smooth climbs) | F5: 75–90 min | G5: N/A (time-based) | H5: 18–20 | I5: Conversational; slow on descents | J5: Templates: Ruck/Walk | K5: Templates: Ruck/Walk
A6: Tue | B6: =IF($B$2="","",$B$2+1) -> 46070 | C6: 3PM | D6: YMCA Strength — Upper + carries + core | E6: Ventura YMCA | F6: 60–75 min | I6: RIR 2 (leave 2 reps in reserve) | J6: Templates: Strength | K6: Templates: Strength
A7: Wed | B7: =IF($B$2="","",$B$2+2) -> 46071 | C7: 10:00 AM | D7: Swim (technique + easy aerobic) + PM brisk walk | E7: YMCA pool + flat route | F7: 60 min swim + 45–75 min walk (2pm) | I7: Easy aerobic + recovery walk | J7: Templates: Swim / Walk | K7: Templates: Swim / Walk
A8: Thu | B8: =IF($B$2="","",$B$2+3) -> 46072 | C8: 1PM | D8: Ruck — Base (flat/rolling) | E8: Harbor route (stable surfaces) | F8: 90–120 min | G8: (miles optional) | H8: 18–20 | I8: Easy; steady rhythm | J8: Templates: Ruck/Walk | K8: Templates: Ruck/Walk
A9: Fri | B9: =IF($B$2="","",$B$2+4) -> 46073 | C9: 0.625 | D9: YMCA Strength — Upper + carries + core | E9: Ventura YMCA | F9: 60–75 min | I9: RIR 2 (leave 2 reps in reserve) | J9: Templates: Strength | K9: Templates: Strength
A10: Sat | B10: =IF($B$2="","",$B$2+5) -> 46074 | C10: 0.5 | D10: Cycling (Zone 2 base) | E10: Home→Ojai or preferred route | F10: 60–180 min | G10: 30–45 mi | I10: Conversational effort | J10: Templates: Cycling | K10: Templates: Cycling
A11: Sun | B11: =IF($B$2="","",$B$2+6) -> 46075 | C11: (choose) | D11: Active recovery (easy swim / mobility / walk) | E11: YMCA or outdoors | F11: 30–60 min | I11: Very easy | J11: Templates | K11: Templates
A13: Strength Log — Tuesday (Upper + Carries + Core)
A14: Exercise | B14: Sets | C14: Reps/Length | D14: Plan Wt | E14: Actual Wt | F14: Notes
A15: Chest press (machine) | B15: 3 | C15: 12 | F15: Warm Up: 10Lbs per side, 2 Sets of 12 Reps. Workout: Set 1: 45LBS. Set 2: 45lbs. Set 3: 40lbs. 12 Reps per set
A16: Lat pulldown (machine) | B16: 3 | C16: 12 | F16: Warm Up Weight: 55lbs 2 Sets of 12 Reps. Workout: Set 1: 100lbs. Set 2: 100lbs. Set 3: 80. 12 Reps per set
A17: Seated row (machine) | B17: 3 | C17: 12 | F17: Warm Up: 55lbs 2 Sets of 12 Reps. Workout: Set 1: 120lbs Set 2: 120lbs Set 3: 100lbs. 12 Reps per set
A18: DB incline or flat press | B18: 3 | C18: 12 | F18: Warm Up: 15lbs 2 Sets of 12 Reps. Workout: Set 1 : 35lbs. Set 2: 35lbs. Set 3: 25lbs. 12 Reps per set
A19: Face pulls / rear delts | B19: 3 | C19: 12 | F19: Warm Up: 25lbs. 2 Set of 12 Reps. Workout: Set 1: 55lbs. Set 2: 55lbs. Set 3: 50lbs. 12 Reps per set
A20: Assited Pull-Ups | B20: 4 | C20: 12 | F20: Set Assited Weights to 175lbs for all 4 sets
A21: Assisted Dips | B21: 4 | C21: 12 | F21: Set Assited Weights to 175lbs for all 4 sets
A22: Farmer carry | B22: 3 | C22: 70–85 yd | F22: Warm Up: 15lbs Length Side. Workout: 50lbs Length Side. 40lbs Length Side. 30lbs Length Side. Perform farmers carry on artifical grass outdoor area.
A23: Dead bug | B23: 3 | C23: 12/side | D23: BW | F23: 2 sets of 12 reps per side
A24: Plank | B24: 3 | C24: 30s | D24: BW | F24: 3 sets of 30 seconds
A26: Strength Log — Friday (Upper + Carries + Core)
A27: Exercise | B27: Sets | C27: Reps | D27: Plan Wt | E27: Actual Wt | F27: Notes
A28: Chest press (machine) | B28: 3 | C28: 12 | F28: Warm Up: 10Lbs per side, 2 Sets of 12 Reps. Workout: Set 1: 45LBS. Set 2: 45lbs. Set 3: 40lbs. 12 Reps per set
A29: Lat pulldown (machine) | B29: 3 | C29: 12 | F29: Warm Up Weight: 55lbs 2 Sets of 12 Reps. Workout: Set 1: 100lbs. Set 2: 100lbs. Set 3: 80. 12 Reps per set
A30: Seated row (machine) | B30: 3 | C30: 12 | F30: Warm Up: 55lbs 2 Sets of 12 Reps. Workout: Set 1: 120lbs Set 2: 120lbs Set 3: 100lbs. 12 Reps per set
A31: DB incline or flat press | B31: 3 | C31: 12 | F31: Warm Up: 15lbs 2 Sets of 12 Reps. Workout: Set 1 : 35lbs. Set 2: 35lbs. Set 3: 25lbs. 12 Reps per set
A32: Face pulls / rear delts | B32: 3 | C32: 12 | F32: Warm Up: 25lbs. 2 Set of 12 Reps. Workout: Set 1: 55lbs. Set 2: 55lbs. Set 3: 50lbs. 12 Reps per set
A33: Assited Pull-Ups | B33: 4 | C33: 12 | F33: Set Assited Weights to 175lbs for all 4 sets
A34: Assisted Dips | B34: 4 | C34: 12 | F34: Set Assited Weights to 175lbs for all 4 sets
A35: Farmer carry | B35: 3 | C35: 70–85 yd | F35: Warm Up: 15lbs Length Side. Workout: 50lbs Length Side. 40lbs Length Side. 30lbs Length Side. Perform farmers carry on artifical grass outdoor area.
A36: Dead bug | B36: 3 | C36: 12/side | D36: BW | F36: 2 sets of 12 reps per side
A37: Plank | B37: 3 | C37: 30s | D37: BW | F37: 3 sets of 30 seconds
A39: Swim Log (Wed 10–11am or Sat Recovery Swim)
A40: Session | B40: Total yards | C40: Main set | D40: Rest | E40: Avg HR | F40: Notes
A41: Planned | B41: 450 yd | C41: Adjust: add 2–6 lengths if recovery is good | D41: 30–45s between lengths
A43: Weekly Summary (auto where possible)
A44: Total ruck miles
A45: Total walk miles
...

Sheet Week 3
A1: Week 3 — Whitney Prep (Training Log)
A2: Week start (Mon): | B2: 46076 | C2: Pack target (lb): | D2: 18–20 | E2: Sleep target: | F2: 8h (aim 10:00pm) | G2: Notes:
A4: Day | B4: Date | C4: Start | D4: Planned Session | E4: Location/Route | F4: Plan Duration | G4: Plan Dist | H4: Pack (lb) | I4: Intensity / Focus | J4: Warm-up | K4: Cool-down | L4: Actual Duration | M4: Actual Dist | N4: Avg HR | O4: Max HR | P4: RPE | Q4: Ailments/Notes
A5: Mon | B5: =IF($B$2="","",$B$2+0) -> 46076 | C5: 1:00 PM | D5: Ruck — Hill time (steady) | E5: Arroyo Verde (choose smooth climbs) | F5: 75–90 min | G5: N/A (time-based) | H5: 18–20 | I5: Conversational; slow on descents | J5: Templates: Ruck/Walk | K5: Templates: Ruck/Walk
A6: Tue | B6: =IF($B$2="","",$B$2+1) -> 46077 | C6: 3PM | D6: YMCA Strength — Upper + carries + core | E6: Ventura YMCA | F6: 60–75 min | I6: RIR 2 (leave 2 reps in reserve) | J6: Templates: Strength | K6: Templates: Strength
A7: Wed | B7: =IF($B$2="","",$B$2+2) -> 46078 | C7: 10:00 AM | D7: Swim (technique + easy aerobic) + PM brisk walk | E7: YMCA pool + flat route | F7: 60 min swim + 45–75 min walk (2pm) | I7: Easy aerobic + recovery walk | J7: Templates: Swim / Walk | K7: Templates: Swim / Walk
A8: Thu | B8: =IF($B$2="","",$B$2+3) -> 46079 | C8: 1PM | D8: Ruck — Base (flat/rolling) | E8: Harbor route (stable surfaces) | F8: 90–120 min | G8: (miles optional) | H8: 18–20 | I8: Easy; steady rhythm | J8: Templates: Ruck/Walk | K8: Templates: Ruck/Walk
A9: Fri | B9: =IF($B$2="","",$B$2+4) -> 46080 | C9: 0.625 | D9: YMCA Strength — Upper + carries + core | E9: Ventura YMCA | F9: 60–75 min | I9: RIR 2 (leave 2 reps in reserve) | J9: Templates: Strength | K9: Templates: Strength
A10: Sat | B10: =IF($B$2="","",$B$2+5) -> 46081 | C10: 0.5 | D10: Cycling (Zone 2 base) | E10: Home→Ojai or preferred route | F10: 60–180 min | G10: 30–45 mi | I10: Conversational effort | J10: Templates: Cycling | K10: Templates: Cycling
A11: Sun | B11: =IF($B$2="","",$B$2+6) -> 46082 | C11: (choose) | D11: Active recovery (easy swim / mobility / walk) | E11: YMCA or outdoors | F11: 30–60 min | I11: Very easy | J11: Templates | K11: Templates
A13: Strength Log — Tuesday (Upper + Carries + Core)
A14: Exercise | B14: Sets | C14: Reps/Length | D14: Plan Wt | E14: Actual Wt | F14: Notes
A15: Chest press (machine) | B15: 3 | C15: 12 | F15: Warm Up: 10Lbs per side, 2 Sets of 12 Reps. Workout: Set 1: 45LBS. Set 2: 45lbs. Set 3: 40lbs. 12 Reps per set
A16: Lat pulldown (machine) | B16: 3 | C16: 12 | F16: Warm Up Weight: 55lbs 2 Sets of 12 Reps. Workout: Set 1: 100lbs. Set 2: 100lbs. Set 3: 80. 12 Reps per set
A17: Seated row (machine) | B17: 3 | C17: 12 | F17: Warm Up: 55lbs 2 Sets of 12 Reps. Workout: Set 1: 120lbs Set 2: 120lbs Set 3: 100lbs. 12 Reps per set
A18: DB incline or flat press | B18: 3 | C18: 12 | F18: Warm Up: 15lbs 2 Sets of 12 Reps. Workout: Set 1 : 35lbs. Set 2: 35lbs. Set 3: 25lbs. 12 Reps per set
A19: Face pulls / rear delts | B19: 3 | C19: 12 | F19: Warm Up: 25lbs. 2 Set of 12 Reps. Workout: Set 1: 55lbs. Set 2: 55lbs. Set 3: 50lbs. 12 Reps per set
A20: Assited Pull-Ups | B20: 4 | C20: 12 | F20: Set Assited Weights to 175lbs for all 4 sets
A21: Assisted Dips | B21: 4 | C21: 12 | F21: Set Assited Weights to 175lbs for all 4 sets
A22: Farmer carry | B22: 3 | C22: 70–85 yd | F22: Warm Up: 15lbs Length Side. Workout: 50lbs Length Side. 40lbs Length Side. 30lbs Length Side. Perform farmers carry on artifical grass outdoor area.
A23: Dead bug | B23: 3 | C23: 12/side | D23: BW | F23: 2 sets of 12 reps per side
A24: Plank | B24: 3 | C24: 30s | D24: BW | F24: 3 sets of 30 seconds
A26: Strength Log — Friday (Upper + Carries + Core)
A27: Exercise | B27: Sets | C27: Reps | D27: Plan Wt | E27: Actual Wt | F27: Notes
A28: Chest press (machine) | B28: 3 | C28: 12 | F28: Warm Up: 10Lbs per side, 2 Sets of 12 Reps. Workout: Set 1: 45LBS. Set 2: 45lbs. Set 3: 40lbs. 12 Reps per set
A29: Lat pulldown (machine) | B29: 3 | C29: 12 | F29: Warm Up Weight: 55lbs 2 Sets of 12 Reps. Workout: Set 1: 100lbs. Set 2: 100lbs. Set 3: 80. 12 Reps per set
A30: Seated row (machine) | B30: 3 | C30: 12 | F30: Warm Up: 55lbs 2 Sets of 12 Reps. Workout: Set 1: 120lbs Set 2: 120lbs Set 3: 100lbs. 12 Reps per set
A31: DB incline or flat press | B31: 3 | C31: 12 | F31: Warm Up: 15lbs 2 Sets of 12 Reps. Workout: Set 1 : 35lbs. Set 2: 35lbs. Set 3: 25lbs. 12 Reps per set
A32: Face pulls / rear delts | B32: 3 | C32: 12 | F32: Warm Up: 25lbs. 2 Set of 12 Reps. Workout: Set 1: 55lbs. Set 2: 55lbs. Set 3: 50lbs. 12 Reps per set
A33: Assited Pull-Ups | B33: 4 | C33: 12 | F33: Set Assited Weights to 175lbs for all 4 sets
A34: Assisted Dips | B34: 4 | C34: 12 | F34: Set Assited Weights to 175lbs for all 4 sets
A35: Farmer carry | B35: 3 | C35: 70–85 yd | F35: Warm Up: 15lbs Length Side. Workout: 50lbs Length Side. 40lbs Length Side. 30lbs Length Side. Perform farmers carry on artifical grass outdoor area.
A36: Dead bug | B36: 3 | C36: 12/side | D36: BW | F36: 2 sets of 12 reps per side
A37: Plank | B37: 3 | C37: 30s | D37: BW | F37: 3 sets of 30 seconds
A39: Swim Log (Wed 10–11am or Sat Recovery Swim)
A40: Session | B40: Total yards | C40: Main set | D40: Rest | E40: Avg HR | F40: Notes
A41: Planned | B41: 550–650 yd | C41: Adjust: add 2–6 lengths if recovery is good | D41: 30–45s between lengths
A43: Weekly Summary (auto where possible)
A44: Total ruck miles
A45: Total walk miles
...

Sheet Week 4
A1: Week 4 — Whitney Prep (Training Log)
A2: Week start (Mon): | B2: 46083 | C2: Pack target (lb): | D2: 18–20 | E2: Sleep target: | F2: 8h (aim 10:00pm) | G2: Notes:
A4: Day | B4: Date | C4: Start | D4: Planned Session | E4: Location/Route | F4: Plan Duration | G4: Plan Dist | H4: Pack (lb) | I4: Intensity / Focus | J4: Warm-up | K4: Cool-down | L4: Actual Duration | M4: Actual Dist | N4: Avg HR | O4: Max HR | P4: RPE | Q4: Ailments/Notes
A5: Mon | B5: =IF($B$2="","",$B$2+0) -> 46083 | C5: 1:00 PM | D5: Ruck — Hill time (steady) | E5: Arroyo Verde (choose smooth climbs) | F5: 75–90 min | G5: N/A (time-based) | H5: 18–20 | I5: Conversational; slow on descents | J5: Templates: Ruck/Walk | K5: Templates: Ruck/Walk
A6: Tue | B6: =IF($B$2="","",$B$2+1) -> 46084 | C6: 3PM | D6: YMCA Strength — Upper + carries + core | E6: Ventura YMCA | F6: 60–75 min | I6: RIR 2 (leave 2 reps in reserve) | J6: Templates: Strength | K6: Templates: Strength
A7: Wed | B7: =IF($B$2="","",$B$2+2) -> 46085 | C7: 10:00 AM | D7: Swim (technique + easy aerobic) + PM brisk walk | E7: YMCA pool + flat route | F7: 60 min swim + 45–75 min walk (2pm) | I7: Easy aerobic + recovery walk | J7: Templates: Swim / Walk | K7: Templates: Swim / Walk
A8: Thu | B8: =IF($B$2="","",$B$2+3) -> 46086 | C8: 1PM | D8: Ruck — Base (flat/rolling) | E8: Harbor route (stable surfaces) | F8: 90–120 min | G8: (miles optional) | H8: 18–20 | I8: Easy; steady rhythm | J8: Templates: Ruck/Walk | K8: Templates: Ruck/Walk
A9: Fri | B9: =IF($B$2="","",$B$2+4) -> 46087 | C9: 0.625 | D9: YMCA Strength — Upper + carries + core | E9: Ventura YMCA | F9: 60–75 min | I9: RIR 2 (leave 2 reps in reserve) | J9: Templates: Strength | K9: Templates: Strength
A10: Sat | B10: =IF($B$2="","",$B$2+5) -> 46088 | C10: 0.5 | D10: Cycling (Zone 2 base) | E10: Home→Ojai or preferred route | F10: 60–180 min | G10: 30–45 mi | I10: Conversational effort | J10: Templates: Cycling | K10: Templates: Cycling
A11: Sun | B11: =IF($B$2="","",$B$2+6) -> 46089 | C11: (choose) | D11: Active recovery (easy swim / mobility / walk) | E11: YMCA or outdoors | F11: 30–60 min | I11: Very easy | J11: Templates | K11: Templates
A13: Strength Log — Tuesday (Upper + Carries + Core)
A14: Exercise | B14: Sets | C14: Reps/Length | D14: Plan Wt | E14: Actual Wt | F14: Notes
A15: Chest press (machine) | B15: 3 | C15: 12 | F15: Warm Up: 10Lbs per side, 2 Sets of 12 Reps. Workout: Set 1: 45LBS. Set 2: 45lbs. Set 3: 40lbs. 12 Reps per set
A16: Lat pulldown (machine) | B16: 3 | C16: 12 | F16: Warm Up Weight: 55lbs 2 Sets of 12 Reps. Workout: Set 1: 100lbs. Set 2: 100lbs. Set 3: 80. 12 Reps per set
A17: Seated row (machine) | B17: 3 | C17: 12 | F17: Warm Up: 55lbs 2 Sets of 12 Reps. Workout: Set 1: 120lbs Set 2: 120lbs Set 3: 100lbs. 12 Reps per set
A18: DB incline or flat press | B18: 3 | C18: 12 | F18: Warm Up: 15lbs 2 Sets of 12 Reps. Workout: Set 1 : 35lbs. Set 2: 35lbs. Set 3: 25lbs. 12 Reps per set
A19: Face pulls / rear delts | B19: 3 | C19: 12 | F19: Warm Up: 25lbs. 2 Set of 12 Reps. Workout: Set 1: 55lbs. Set 2: 55lbs. Set 3: 50lbs. 12 Reps per set
A20: Assited Pull-Ups | B20: 4 | C20: 12 | F20: Set Assited Weights to 175lbs for all 4 sets
A21: Assisted Dips | B21: 4 | C21: 12 | F21: Set Assited Weights to 175lbs for all 4 sets
A22: Farmer carry | B22: 3 | C22: 70–85 yd | F22: Warm Up: 15lbs Length Side. Workout: 50lbs Length Side. 40lbs Length Side. 30lbs Length Side. Perform farmers carry on artifical grass outdoor area.
A23: Dead bug | B23: 3 | C23: 12/side | D23: BW | F23: 2 sets of 12 reps per side
A24: Plank | B24: 3 | C24: 30s | D24: BW | F24: 3 sets of 30 seconds
A26: Strength Log — Friday (Upper + Carries + Core)
A27: Exercise | B27: Sets | C27: Reps | D27: Plan Wt | E27: Actual Wt | F27: Notes
A28: Chest press (machine) | B28: 3 | C28: 12 | F28: Warm Up: 10Lbs per side, 2 Sets of 12 Reps. Workout: Set 1: 45LBS. Set 2: 45lbs. Set 3: 40lbs. 12 Reps per set
A29: Lat pulldown (machine) | B29: 3 | C29: 12 | F29: Warm Up Weight: 55lbs 2 Sets of 12 Reps. Workout: Set 1: 100lbs. Set 2: 100lbs. Set 3: 80. 12 Reps per set
A30: Seated row (machine) | B30: 3 | C30: 12 | F30: Warm Up: 55lbs 2 Sets of 12 Reps. Workout: Set 1: 120lbs Set 2: 120lbs Set 3: 100lbs. 12 Reps per set
A31: DB incline or flat press | B31: 3 | C31: 12 | F31: Warm Up: 15lbs 2 Sets of 12 Reps. Workout: Set 1 : 35lbs. Set 2: 35lbs. Set 3: 25lbs. 12 Reps per set
A32: Face pulls / rear delts | B32: 3 | C32: 12 | F32: Warm Up: 25lbs. 2 Set of 12 Reps. Workout: Set 1: 55lbs. Set 2: 55lbs. Set 3: 50lbs. 12 Reps per set
A33: Assited Pull-Ups | B33: 4 | C33: 12 | F33: Set Assited Weights to 175lbs for all 4 sets
A34: Assisted Dips | B34: 4 | C34: 12 | F34: Set Assited Weights to 175lbs for all 4 sets
A35: Farmer carry | B35: 3 | C35: 70–85 yd | F35: Warm Up: 15lbs Length Side. Workout: 50lbs Length Side. 40lbs Length Side. 30lbs Length Side. Perform farmers carry on artifical grass outdoor area.
A36: Dead bug | B36: 3 | C36: 12/side | D36: BW | F36: 2 sets of 12 reps per side
A37: Plank | B37: 3 | C37: 30s | D37: BW | F37: 3 sets of 30 seconds
A39: Swim Log (Wed 10–11am or Sat Recovery Swim)
A40: Session | B40: Total yards | C40: Main set | D40: Rest | E40: Avg HR | F40: Notes
A41: Planned | B41: 350–450 yd | C41: Adjust: add 2–6 lengths if recovery is good | D41: 30–45s between lengths
A43: Weekly Summary (auto where possible)
A44: Total ruck miles
A45: Total walk miles
...
